[2025-04-26T01:19:37.918+0000] {local_task_job_runner.py:123} INFO - ::group::Pre task execution logs
[2025-04-26T01:19:37.942+0000] {taskinstance.py:2614} INFO - Dependencies all met for dep_context=non-requeueable deps ti=<TaskInstance: user_processing.store_user manual__2025-04-26T01:18:55.389251+00:00 [queued]>
[2025-04-26T01:19:37.956+0000] {taskinstance.py:2614} INFO - Dependencies all met for dep_context=requeueable deps ti=<TaskInstance: user_processing.store_user manual__2025-04-26T01:18:55.389251+00:00 [queued]>
[2025-04-26T01:19:37.957+0000] {taskinstance.py:2867} INFO - Starting attempt 1 of 1
[2025-04-26T01:19:38.134+0000] {taskinstance.py:2890} INFO - Executing <Task(PythonOperator): store_user> on 2025-04-26 01:18:55.389251+00:00
[2025-04-26T01:19:38.142+0000] {warnings.py:112} WARNING - /home/***/.local/lib/python3.12/site-packages/***/task/task_runner/standard_task_runner.py:70: DeprecationWarning: This process (pid=2431) is multi-threaded, use of fork() may lead to deadlocks in the child.
  pid = os.fork()

[2025-04-26T01:19:38.146+0000] {standard_task_runner.py:72} INFO - Started process 2433 to run task
[2025-04-26T01:19:38.146+0000] {standard_task_runner.py:104} INFO - Running: ['***', 'tasks', 'run', 'user_processing', 'store_user', 'manual__2025-04-26T01:18:55.389251+00:00', '--job-id', '38', '--raw', '--subdir', 'DAGS_FOLDER/user_processing.py', '--cfg-path', '/tmp/tmpvsvon8g0']
[2025-04-26T01:19:38.150+0000] {standard_task_runner.py:105} INFO - Job 38: Subtask store_user
[2025-04-26T01:19:38.207+0000] {task_command.py:467} INFO - Running <TaskInstance: user_processing.store_user manual__2025-04-26T01:18:55.389251+00:00 [running]> on host bb0d27cab5a5
[2025-04-26T01:19:38.300+0000] {taskinstance.py:3134} INFO - Exporting env vars: AIRFLOW_CTX_DAG_OWNER='***' AIRFLOW_CTX_DAG_ID='user_processing' AIRFLOW_CTX_TASK_ID='store_user' AIRFLOW_CTX_EXECUTION_DATE='2025-04-26T01:18:55.389251+00:00' AIRFLOW_CTX_TRY_NUMBER='1' AIRFLOW_CTX_DAG_RUN_ID='manual__2025-04-26T01:18:55.389251+00:00'
[2025-04-26T01:19:38.302+0000] {taskinstance.py:732} INFO - ::endgroup::
[2025-04-26T01:19:38.319+0000] {postgres.py:180} INFO - Running copy expert: COPY users FROM stdin WITH DELIMITER AS ',' , filename: /tmp/processed_user.csv
[2025-04-26T01:19:38.329+0000] {base.py:84} INFO - Retrieving connection 'postgres'
[2025-04-26T01:19:38.335+0000] {taskinstance.py:3313} ERROR - Task failed with exception
Traceback (most recent call last):
  File "/home/airflow/.local/lib/python3.12/site-packages/airflow/models/taskinstance.py", line 768, in _execute_task
    result = _execute_callable(context=context, **execute_callable_kwargs)
             ^^^^^^^^^^^^^^^^^^^^^^^^^^^^^^^^^^^^^^^^^^^^^^^^^^^^^^^^^^^^^
  File "/home/airflow/.local/lib/python3.12/site-packages/airflow/models/taskinstance.py", line 734, in _execute_callable
    return ExecutionCallableRunner(
           ^^^^^^^^^^^^^^^^^^^^^^^^
  File "/home/airflow/.local/lib/python3.12/site-packages/airflow/utils/operator_helpers.py", line 252, in run
    return self.func(*args, **kwargs)
           ^^^^^^^^^^^^^^^^^^^^^^^^^^
  File "/home/airflow/.local/lib/python3.12/site-packages/airflow/models/baseoperator.py", line 424, in wrapper
    return func(self, *args, **kwargs)
           ^^^^^^^^^^^^^^^^^^^^^^^^^^^
  File "/home/airflow/.local/lib/python3.12/site-packages/airflow/operators/python.py", line 238, in execute
    return_value = self.execute_callable()
                   ^^^^^^^^^^^^^^^^^^^^^^^
  File "/home/airflow/.local/lib/python3.12/site-packages/airflow/operators/python.py", line 256, in execute_callable
    return runner.run(*self.op_args, **self.op_kwargs)
           ^^^^^^^^^^^^^^^^^^^^^^^^^^^^^^^^^^^^^^^^^^^
  File "/home/airflow/.local/lib/python3.12/site-packages/airflow/utils/operator_helpers.py", line 252, in run
    return self.func(*args, **kwargs)
           ^^^^^^^^^^^^^^^^^^^^^^^^^^
  File "/opt/airflow/dags/user_processing.py", line 29, in _store_user
    hook.copy_expert(
  File "/home/airflow/.local/lib/python3.12/site-packages/airflow/providers/postgres/hooks/postgres.py", line 186, in copy_expert
    cur.copy_expert(sql, file)
psycopg2.errors.UndefinedTable: relation "users" does not exist

[2025-04-26T01:19:38.352+0000] {taskinstance.py:1226} INFO - Marking task as FAILED. dag_id=user_processing, task_id=store_user, run_id=manual__2025-04-26T01:18:55.389251+00:00, execution_date=20250426T011855, start_date=20250426T011937, end_date=20250426T011938
[2025-04-26T01:19:38.377+0000] {taskinstance.py:341} INFO - ::group::Post task execution logs
[2025-04-26T01:19:38.379+0000] {standard_task_runner.py:124} ERROR - Failed to execute job 38 for task store_user (relation "users" does not exist
; 2433)
Traceback (most recent call last):
  File "/home/airflow/.local/lib/python3.12/site-packages/airflow/task/task_runner/standard_task_runner.py", line 117, in _start_by_fork
    ret = args.func(args, dag=self.dag)
          ^^^^^^^^^^^^^^^^^^^^^^^^^^^^^
  File "/home/airflow/.local/lib/python3.12/site-packages/airflow/cli/cli_config.py", line 49, in command
    return func(*args, **kwargs)
           ^^^^^^^^^^^^^^^^^^^^^
  File "/home/airflow/.local/lib/python3.12/site-packages/airflow/utils/cli.py", line 116, in wrapper
    return f(*args, **kwargs)
           ^^^^^^^^^^^^^^^^^^
  File "/home/airflow/.local/lib/python3.12/site-packages/airflow/cli/commands/task_command.py", line 483, in task_run
    task_return_code = _run_task_by_selected_method(args, _dag, ti)
                       ^^^^^^^^^^^^^^^^^^^^^^^^^^^^^^^^^^^^^^^^^^^^
  File "/home/airflow/.local/lib/python3.12/site-packages/airflow/cli/commands/task_command.py", line 256, in _run_task_by_selected_method
    return _run_raw_task(args, ti)
           ^^^^^^^^^^^^^^^^^^^^^^^
  File "/home/airflow/.local/lib/python3.12/site-packages/airflow/cli/commands/task_command.py", line 341, in _run_raw_task
    return ti._run_raw_task(
           ^^^^^^^^^^^^^^^^^
  File "/home/airflow/.local/lib/python3.12/site-packages/airflow/utils/session.py", line 97, in wrapper
    return func(*args, session=session, **kwargs)
           ^^^^^^^^^^^^^^^^^^^^^^^^^^^^^^^^^^^^^^
  File "/home/airflow/.local/lib/python3.12/site-packages/airflow/models/taskinstance.py", line 3006, in _run_raw_task
    return _run_raw_task(
           ^^^^^^^^^^^^^^
  File "/home/airflow/.local/lib/python3.12/site-packages/airflow/models/taskinstance.py", line 274, in _run_raw_task
    TaskInstance._execute_task_with_callbacks(
  File "/home/airflow/.local/lib/python3.12/site-packages/airflow/models/taskinstance.py", line 3161, in _execute_task_with_callbacks
    result = self._execute_task(context, task_orig)
             ^^^^^^^^^^^^^^^^^^^^^^^^^^^^^^^^^^^^^^
  File "/home/airflow/.local/lib/python3.12/site-packages/airflow/models/taskinstance.py", line 3185, in _execute_task
    return _execute_task(self, context, task_orig)
           ^^^^^^^^^^^^^^^^^^^^^^^^^^^^^^^^^^^^^^^
  File "/home/airflow/.local/lib/python3.12/site-packages/airflow/models/taskinstance.py", line 768, in _execute_task
    result = _execute_callable(context=context, **execute_callable_kwargs)
             ^^^^^^^^^^^^^^^^^^^^^^^^^^^^^^^^^^^^^^^^^^^^^^^^^^^^^^^^^^^^^
  File "/home/airflow/.local/lib/python3.12/site-packages/airflow/models/taskinstance.py", line 734, in _execute_callable
    return ExecutionCallableRunner(
           ^^^^^^^^^^^^^^^^^^^^^^^^
  File "/home/airflow/.local/lib/python3.12/site-packages/airflow/utils/operator_helpers.py", line 252, in run
    return self.func(*args, **kwargs)
           ^^^^^^^^^^^^^^^^^^^^^^^^^^
  File "/home/airflow/.local/lib/python3.12/site-packages/airflow/models/baseoperator.py", line 424, in wrapper
    return func(self, *args, **kwargs)
           ^^^^^^^^^^^^^^^^^^^^^^^^^^^
  File "/home/airflow/.local/lib/python3.12/site-packages/airflow/operators/python.py", line 238, in execute
    return_value = self.execute_callable()
                   ^^^^^^^^^^^^^^^^^^^^^^^
  File "/home/airflow/.local/lib/python3.12/site-packages/airflow/operators/python.py", line 256, in execute_callable
    return runner.run(*self.op_args, **self.op_kwargs)
           ^^^^^^^^^^^^^^^^^^^^^^^^^^^^^^^^^^^^^^^^^^^
  File "/home/airflow/.local/lib/python3.12/site-packages/airflow/utils/operator_helpers.py", line 252, in run
    return self.func(*args, **kwargs)
           ^^^^^^^^^^^^^^^^^^^^^^^^^^
  File "/opt/airflow/dags/user_processing.py", line 29, in _store_user
    hook.copy_expert(
  File "/home/airflow/.local/lib/python3.12/site-packages/airflow/providers/postgres/hooks/postgres.py", line 186, in copy_expert
    cur.copy_expert(sql, file)
psycopg2.errors.UndefinedTable: relation "users" does not exist

[2025-04-26T01:19:38.404+0000] {local_task_job_runner.py:266} INFO - Task exited with return code 1
[2025-04-26T01:19:38.430+0000] {taskinstance.py:3901} INFO - 0 downstream tasks scheduled from follow-on schedule check
[2025-04-26T01:19:38.434+0000] {local_task_job_runner.py:245} INFO - ::endgroup::
