[2025-04-26T01:08:47.452+0000] {local_task_job_runner.py:123} INFO - ::group::Pre task execution logs
[2025-04-26T01:08:47.475+0000] {taskinstance.py:2614} INFO - Dependencies all met for dep_context=non-requeueable deps ti=<TaskInstance: user_processing.process_user manual__2025-04-26T01:08:02.073364+00:00 [queued]>
[2025-04-26T01:08:47.489+0000] {taskinstance.py:2614} INFO - Dependencies all met for dep_context=requeueable deps ti=<TaskInstance: user_processing.process_user manual__2025-04-26T01:08:02.073364+00:00 [queued]>
[2025-04-26T01:08:47.490+0000] {taskinstance.py:2867} INFO - Starting attempt 1 of 1
[2025-04-26T01:08:47.669+0000] {taskinstance.py:2890} INFO - Executing <Task(PythonOperator): process_user> on 2025-04-26 01:08:02.073364+00:00
[2025-04-26T01:08:47.677+0000] {warnings.py:112} WARNING - /home/***/.local/lib/python3.12/site-packages/***/task/task_runner/standard_task_runner.py:70: DeprecationWarning: This process (pid=2242) is multi-threaded, use of fork() may lead to deadlocks in the child.
  pid = os.fork()

[2025-04-26T01:08:47.680+0000] {standard_task_runner.py:72} INFO - Started process 2244 to run task
[2025-04-26T01:08:47.679+0000] {standard_task_runner.py:104} INFO - Running: ['***', 'tasks', 'run', 'user_processing', 'process_user', 'manual__2025-04-26T01:08:02.073364+00:00', '--job-id', '24', '--raw', '--subdir', 'DAGS_FOLDER/user_processing.py', '--cfg-path', '/tmp/tmpltja72ia']
[2025-04-26T01:08:47.682+0000] {standard_task_runner.py:105} INFO - Job 24: Subtask process_user
[2025-04-26T01:08:47.746+0000] {task_command.py:467} INFO - Running <TaskInstance: user_processing.process_user manual__2025-04-26T01:08:02.073364+00:00 [running]> on host bb0d27cab5a5
[2025-04-26T01:08:47.837+0000] {taskinstance.py:3134} INFO - Exporting env vars: AIRFLOW_CTX_DAG_OWNER='***' AIRFLOW_CTX_DAG_ID='user_processing' AIRFLOW_CTX_TASK_ID='process_user' AIRFLOW_CTX_EXECUTION_DATE='2025-04-26T01:08:02.073364+00:00' AIRFLOW_CTX_TRY_NUMBER='1' AIRFLOW_CTX_DAG_RUN_ID='manual__2025-04-26T01:08:02.073364+00:00'
[2025-04-26T01:08:47.839+0000] {taskinstance.py:732} INFO - ::endgroup::
[2025-04-26T01:08:47.871+0000] {user_processing.py:17} INFO - XCom data: {'results': [{'gender': 'male', 'name': {'title': 'Mr', 'first': 'Druso', 'last': 'Cardoso'}, 'location': {'street': {'number': 7245, 'name': 'Rua Um'}, 'city': 'Jaú', 'state': 'Amapá', 'country': 'Brazil', 'postcode': 93841, 'coordinates': {'latitude': '-77.4890', 'longitude': '-178.8705'}, 'timezone': {'offset': '-9:00', 'description': 'Alaska'}}, 'email': 'druso.cardoso@example.com', 'login': {'uuid': '411be71e-8bd1-4122-a8cd-d8bdc8130d61', 'username': 'silversnake841', 'password': '***', 'salt': 'HUYgejiQ', 'md5': '13e941ed624d79f862bcdb609ac36e8e', 'sha1': '0d01bac1afd18c59c63c1ba9ca2569cac91244a0', 'sha256': '34a142a57850394914dc7173e6d7e691ff9e623d0b56a774679d9d87bc407345'}, 'dob': {'date': '1974-08-31T02:24:49.967Z', 'age': 50}, 'registered': {'date': '2016-07-08T19:17:53.552Z', 'age': 8}, 'phone': '(75) 1208-4040', 'cell': '(40) 2059-9736', 'id': {'name': 'CPF', 'value': '302.714.918-07'}, 'picture': {'large': 'https://randomuser.me/api/portraits/men/85.jpg', 'medium': 'https://randomuser.me/api/portraits/med/men/85.jpg', 'thumbnail': 'https://randomuser.me/api/portraits/thumb/men/85.jpg'}, 'nat': 'BR'}], 'info': {'seed': 'a69c5862fd6304f9', 'results': 1, 'page': 1, 'version': '1.4'}}
[2025-04-26T01:08:47.872+0000] {taskinstance.py:3313} ERROR - Task failed with exception
Traceback (most recent call last):
  File "/home/airflow/.local/lib/python3.12/site-packages/airflow/models/taskinstance.py", line 768, in _execute_task
    result = _execute_callable(context=context, **execute_callable_kwargs)
             ^^^^^^^^^^^^^^^^^^^^^^^^^^^^^^^^^^^^^^^^^^^^^^^^^^^^^^^^^^^^^
  File "/home/airflow/.local/lib/python3.12/site-packages/airflow/models/taskinstance.py", line 734, in _execute_callable
    return ExecutionCallableRunner(
           ^^^^^^^^^^^^^^^^^^^^^^^^
  File "/home/airflow/.local/lib/python3.12/site-packages/airflow/utils/operator_helpers.py", line 252, in run
    return self.func(*args, **kwargs)
           ^^^^^^^^^^^^^^^^^^^^^^^^^^
  File "/home/airflow/.local/lib/python3.12/site-packages/airflow/models/baseoperator.py", line 424, in wrapper
    return func(self, *args, **kwargs)
           ^^^^^^^^^^^^^^^^^^^^^^^^^^^
  File "/home/airflow/.local/lib/python3.12/site-packages/airflow/operators/python.py", line 238, in execute
    return_value = self.execute_callable()
                   ^^^^^^^^^^^^^^^^^^^^^^^
  File "/home/airflow/.local/lib/python3.12/site-packages/airflow/operators/python.py", line 256, in execute_callable
    return runner.run(*self.op_args, **self.op_kwargs)
           ^^^^^^^^^^^^^^^^^^^^^^^^^^^^^^^^^^^^^^^^^^^
  File "/home/airflow/.local/lib/python3.12/site-packages/airflow/utils/operator_helpers.py", line 252, in run
    return self.func(*args, **kwargs)
           ^^^^^^^^^^^^^^^^^^^^^^^^^^
  File "/opt/airflow/dags/user_processing.py", line 18, in _process_user
    user = user['result'][0]
       ~~~~^^^^^^^^^^
KeyError: 'result'
[2025-04-26T01:08:47.885+0000] {taskinstance.py:1226} INFO - Marking task as FAILED. dag_id=user_processing, task_id=process_user, run_id=manual__2025-04-26T01:08:02.073364+00:00, execution_date=20250426T010802, start_date=20250426T010847, end_date=20250426T010847
[2025-04-26T01:08:47.909+0000] {taskinstance.py:341} INFO - ::group::Post task execution logs
[2025-04-26T01:08:47.910+0000] {standard_task_runner.py:124} ERROR - Failed to execute job 24 for task process_user ('result'; 2244)
Traceback (most recent call last):
  File "/home/airflow/.local/lib/python3.12/site-packages/airflow/task/task_runner/standard_task_runner.py", line 117, in _start_by_fork
    ret = args.func(args, dag=self.dag)
          ^^^^^^^^^^^^^^^^^^^^^^^^^^^^^
  File "/home/airflow/.local/lib/python3.12/site-packages/airflow/cli/cli_config.py", line 49, in command
    return func(*args, **kwargs)
           ^^^^^^^^^^^^^^^^^^^^^
  File "/home/airflow/.local/lib/python3.12/site-packages/airflow/utils/cli.py", line 116, in wrapper
    return f(*args, **kwargs)
           ^^^^^^^^^^^^^^^^^^
  File "/home/airflow/.local/lib/python3.12/site-packages/airflow/cli/commands/task_command.py", line 483, in task_run
    task_return_code = _run_task_by_selected_method(args, _dag, ti)
                       ^^^^^^^^^^^^^^^^^^^^^^^^^^^^^^^^^^^^^^^^^^^^
  File "/home/airflow/.local/lib/python3.12/site-packages/airflow/cli/commands/task_command.py", line 256, in _run_task_by_selected_method
    return _run_raw_task(args, ti)
           ^^^^^^^^^^^^^^^^^^^^^^^
  File "/home/airflow/.local/lib/python3.12/site-packages/airflow/cli/commands/task_command.py", line 341, in _run_raw_task
    return ti._run_raw_task(
           ^^^^^^^^^^^^^^^^^
  File "/home/airflow/.local/lib/python3.12/site-packages/airflow/utils/session.py", line 97, in wrapper
    return func(*args, session=session, **kwargs)
           ^^^^^^^^^^^^^^^^^^^^^^^^^^^^^^^^^^^^^^
  File "/home/airflow/.local/lib/python3.12/site-packages/airflow/models/taskinstance.py", line 3006, in _run_raw_task
    return _run_raw_task(
           ^^^^^^^^^^^^^^
  File "/home/airflow/.local/lib/python3.12/site-packages/airflow/models/taskinstance.py", line 274, in _run_raw_task
    TaskInstance._execute_task_with_callbacks(
  File "/home/airflow/.local/lib/python3.12/site-packages/airflow/models/taskinstance.py", line 3161, in _execute_task_with_callbacks
    result = self._execute_task(context, task_orig)
             ^^^^^^^^^^^^^^^^^^^^^^^^^^^^^^^^^^^^^^
  File "/home/airflow/.local/lib/python3.12/site-packages/airflow/models/taskinstance.py", line 3185, in _execute_task
    return _execute_task(self, context, task_orig)
           ^^^^^^^^^^^^^^^^^^^^^^^^^^^^^^^^^^^^^^^
  File "/home/airflow/.local/lib/python3.12/site-packages/airflow/models/taskinstance.py", line 768, in _execute_task
    result = _execute_callable(context=context, **execute_callable_kwargs)
             ^^^^^^^^^^^^^^^^^^^^^^^^^^^^^^^^^^^^^^^^^^^^^^^^^^^^^^^^^^^^^
  File "/home/airflow/.local/lib/python3.12/site-packages/airflow/models/taskinstance.py", line 734, in _execute_callable
    return ExecutionCallableRunner(
           ^^^^^^^^^^^^^^^^^^^^^^^^
  File "/home/airflow/.local/lib/python3.12/site-packages/airflow/utils/operator_helpers.py", line 252, in run
    return self.func(*args, **kwargs)
           ^^^^^^^^^^^^^^^^^^^^^^^^^^
  File "/home/airflow/.local/lib/python3.12/site-packages/airflow/models/baseoperator.py", line 424, in wrapper
    return func(self, *args, **kwargs)
           ^^^^^^^^^^^^^^^^^^^^^^^^^^^
  File "/home/airflow/.local/lib/python3.12/site-packages/airflow/operators/python.py", line 238, in execute
    return_value = self.execute_callable()
                   ^^^^^^^^^^^^^^^^^^^^^^^
  File "/home/airflow/.local/lib/python3.12/site-packages/airflow/operators/python.py", line 256, in execute_callable
    return runner.run(*self.op_args, **self.op_kwargs)
           ^^^^^^^^^^^^^^^^^^^^^^^^^^^^^^^^^^^^^^^^^^^
  File "/home/airflow/.local/lib/python3.12/site-packages/airflow/utils/operator_helpers.py", line 252, in run
    return self.func(*args, **kwargs)
           ^^^^^^^^^^^^^^^^^^^^^^^^^^
  File "/opt/airflow/dags/user_processing.py", line 18, in _process_user
    user = user['result'][0]
       ~~~~^^^^^^^^^^
KeyError: 'result'
[2025-04-26T01:08:47.939+0000] {local_task_job_runner.py:266} INFO - Task exited with return code 1
[2025-04-26T01:08:47.966+0000] {taskinstance.py:3901} INFO - 0 downstream tasks scheduled from follow-on schedule check
[2025-04-26T01:08:47.972+0000] {local_task_job_runner.py:245} INFO - ::endgroup::
